Workbook

Sheet Raw_Data
A1: Order ID | B1: Order Date | C1: Customer Name | D1: Region | E1: Category | F1: Sub-Category | G1: Product | H1: Quantity | I1: Unit Price | J1: Cost Price | K1: Discount | L1: Sales
A2: 100001 | B2: 24-Nov-2024 | C2: VIKRAM RAO | D2: north | E2: Electronics | F2: Monitors | G2: ViewClear 24 | H2: 4 | I2: 9197.33 | J2: 5702.34 | L2: 36789.32
A3: 100002 | B3: 12/14/2024 | C3: RIYA PATEL | D3: west | E3: furniture | F3: cabinets | G3: StorageMax Wood | H3: 1 | I3: 4928.63 | J3: 3105.04 | K3: 0 | L3: 4928.63
A4: 100003 | B4: 02/18/2024 | C4: SIMRAN BHATT | D4: EAST | E4: electronics | F4: Keyboards | G4: GamerEdge RGB | H4: 2 | I4: 3337.17 | J4: 1668.58 | K4: 0.1 | L4: 6006.9
A5: 100004 | B5: 06/06/2024 | C5: saanvi iyer | D5: NORTH | E5: furniture | F5: Chairs | G5: ClassicWood | H5: 5 | I5: 5246.51 | J5: 3410.23 | K5: 0.2 | L5: 20986.02
A6: 100005 | B6: 18-Dec-2024 | C6: PRIYA KAPOOR | D6: SOUTH | E6: furniture | F6: cabinets | G6: StorageMax Wood | H6: 5 | I6: 5069.6 | J6: 3193.85 | K6: 0.15 | L6: 21545.79
A7: 100006 | B7: 08/05/2024 | C7: Kabir Nair | D7: south | E7: Office Supplies | F7: pens | G7: InkFlow Gel Pack5 | H7: 7 | I7: 127.8 | J7: 57.51 | K7: 0.15 | L7: 760.42
A8: 100007 | B8: 14-Nov-2024 | C8: myra malhotra | D8: South | E8: Clothing | F8: t-shirts | G8: CottonBasic | H8: 2 | I8: 436.44 | J8: 196.4 | K8: 0 | L8: 872.88
A9: 100008 | B9: 01/31/2024 | C9: pooja reddy | D9: North | E9: Office Supplies | F9: STAPLERS | G9: ClickFix Standard | H9: 5 | I9: 221.43 | J9: 110.72 | K9: 0.1 | L9: 996.45
A10: 100009 | B10: 06/29/2024 | C10: ARJUN VERMA | D10: East | E10: Furniture | F10: Chairs | G10: MeshFlex Pro | H10: 6 | I10: 7195.98 | J10: 4461.51 | K10: 0 | L10: 43175.9
A11: 100010 | B11: 31-Jul-2024 | C11: Meera Shah | D11: south | E11: furniture | F11: cabinets | G11: FileSafe Steel | H11: 5 | I11: 5704.15 | J11: 3422.49 | K11: 0.1 | L11: 25668.66
A12: 100011 | B12: 08-Sep-2024 | C12: AARAV GUPTA | D12: WEST | E12: electronics | F12: Headphones | G12: SoundMax Pro | H12: 2 | I12: 2484.88 | J12: 1366.68 | K12: 0.1 | L12: 4472.78
A13: 100012 | B13: 16-Oct-2024 | C13: NIKHIL DAS | D13: east | E13: clothing | F13: Jackets | G13: WinterGuard | H13: 12 | I13: 3000.53 | J13: 1500.26 | K13: 0.1 | L13: 32405.69
A14: 100013 | B14: 08-Feb-2024 | C14: sai shah | D14: NORTH | E14: Electronics | F14: laptops | G14: UltraSlim X1 | H14: 12 | I14: 61634.78 | J14: 36980.87 | K14: 0.2 | L14: 591693.88
A15: 100014 | B15: 08/07/2024 | C15: pranav verma | D15: North | E15: Electronics | F15: laptops | G15: ProBook 14 | H15: 4 | I15: 43722.92 | J15: 28419.9 | K15: 0.1
A16: 100015 | B16: 18-Dec-2024 | C16: Tanvi Kapoor | D16: West | E16: FURNITURE | F16: Desks | G16: CornerFit Desk | H16: 4 | I16: 10544.14 | J16: 6115.6 | K16: 0.1 | L16: 37958.89
A17: 100016 | B17: 04-Jul-2024 | C17: vikram bhatt | D17: North | E17: furniture | F17: chairs | G17: MeshFlex Pro | H17: 2 | I17: 7368.22 | J17: 4568.3 | L17: 14736.44
A18: 100017 | B18: 11-Aug-2024 | C18: AARAV BOSE | D18: East | E18: Furniture | F18: BOOKSHELVES | G18: MetalFrame Open | H18: 3 | I18: 3008.23 | J18: 1865.1 | K18: 0.05 | L18: 8573.45
A19: 100018 | B19: 09/23/2024 | C19: sneha pillai | D19: east | E19: Electronics | F19: HEADPHONES | G19: BassBeat Mini | H19: 5 | I19: 1164.61 | J19: 698.77 | L19: 4658.43
A20: 100019 | B20: 06/07/2024 | C20: POOJA DAS | D20: north | E20: Electronics | F20: HEADPHONES | G20: BassBeat Mini | H20: 5 | I20: 1234.35 | J20: 740.61 | K20: 0.15 | L20: 5246
A21: 100020 | B21: 18-Jul-2024 | C21: ISHAAN GUPTA | D21: EAST | E21: furniture | F21: Bookshelves | G21: WoodCraft 5-Tier | H21: 12 | I21: 3425.29 | J21: 2055.17 | K21: 0.15 | L21: 34937.97
A22: 100021 | B22: 01/29/2024 | C22: Sai Nair | D22: West | E22: Furniture | F22: Chairs | G22: ClassicWood | H22: 6 | I22: 5547.71 | J22: 3606.01 | K22: 0.2 | L22: 26629.02
A23: 100022 | B23: 26-Jul-2024 | C23: Riya Reddy | D23: South | E23: FURNITURE | F23: Desks | G23: CornerFit Desk | H23: 1 | I23: 9538.51 | J23: 5532.33 | K23: 0.05 | L23: 9061.58
A24: 100023 | B24: 07/11/2024 | C24: yash gupta | D24: west | E24: Office Supplies | F24: Staplers | G24: ClickFix Standard | H24: 4 | I24: 209.68 | J24: 104.84 | K24: 0 | L24: 838.71
A25: 100024 | B25: 01/04/2024 | C25: SAANVI KAPOOR | D25: North | E25: ELECTRONICS | F25: MONITORS | G25: ViewClear 24 | H25: 10 | I25: 10213.73 | J25: 6332.51 | K25: 0.05 | L25: 97030.43
A26: 100025 | B26: 06/20/2024 | C26: priya singh | D26: west | E26: electronics | F26: headphones | G26: BassBeat Mini | H26: 7 | I26: 1150.92 | J26: 690.55 | K26: 0.15 | L26: 6847.95
A27: 100026 | B27: 10/19/2024 | C27: MYRA SHAH | D27: South | E27: furniture | F27: cabinets | G27: StorageMax Wood | H27: 11 | I27: 4922.11 | J27: 3100.93 | K27: 0 | L27: 54143.21
A28: 100027 | B28: 05/17/2024 | C28: ADITYA NAIR | D28: WEST | E28: CLOTHING | F28: Jackets | G28: RainShield Pro | H28: 12 | I28: 2138.53 | J28: 1069.27 | K28: 0 | L28: 25662.38
A29: 100028 | B29: 08-Jul-2024 | C29: Manoj Sharma | D29: North | E29: CLOTHING | F29: Bags | G29: CityCarry Backpack | H29: 12 | I29: 1560.79 | J29: 780.39 | K29: 0.1 | L29: 16856.52
A30: 100029 | B30: 11/17/2024 | C30: Aman Bose | D30: West | E30: Electronics | F30: Headphones | G30: SoundMax Pro | H30: 8 | I30: 2418.34 | J30: 1330.08 | K30: 0.1 | L30: 17412.01
A31: 100030 | B31: 16-Sep-2024 | C31: riya bose | D31: west | E31: Clothing | F31: SHOES | G31: WalkEase Casual | H31: 11 | I31: 1873.5 | J31: 936.75 | K31: 0.2 | L31: 16486.76
... A49: 100048 | B49: 03/16/2024 | C49: meera joshi | D49: North | E49: FURNITURE | F49: chairs | G49: MeshFlex Pro | H49: 5 | I49: 7276.88 | J49: 4511.66 | K49: 0.2 | L49: 29107.5
A50: 100049 | B50: 05/22/2024 | C50: simran shah | D50: EAST | E50: Office Supplies | F50: Paper | G50: PrintPro A4 Ream | H50: 6 | I50: 280.98 | J50: 140.49 | L50: 1517.31
A51: 100050 | B51: 08/21/2024 | C51: Aman Verma | D51: north | E51: clothing | F51: BAGS | G51: CityCarry Backpack | H51: 4 | I51: 1526.1 | J51: 763.05 | K51: 0.1 | L51: 5493.94
A52: 100051 | B52: 15-Feb-2024 | C52: Manoj Patel | D52: south | E52: Furniture | F52: Bookshelves | G52: WoodCraft 5-Tier | H52: 9 | I52: 3410.33 | J52: 2046.2 | K52: 0 | L52: 30692.99
A53: 100052 | B53: 29-Dec-2024 | C53: yash gupta | D53: South | E53: Clothing | F53: Jackets | G53: RainShield Pro | H53: 4 | I53: 2353.65 | J53: 1176.83 | K53: 0.1 | L53: 8473.16
A54: 100053 | B54: 06/18/2024 | C54: KIARA KAPOOR | D54: east | E54: Office Supplies | F54: binders | G54: RingFile A4 | H54: 8 | I54: 183.6 | J54: 88.13 | K54: 0.05 | L54: 1395.38
A55: 100054 | B55: 16-Mar-2024 | C55: KABIR PILLAI | D55: East | E55: CLOTHING | F55: Bags | G55: TravelMax Duffel | H55: 11 | I55: 1895.42 | J55: 947.71 | K55: 0.15 | L55: 17722.18
A56: 100055 | B56: 06/20/2024 | C56: Manoj Gupta | D56: north | E56: furniture | F56: Cabinets | G56: FileSafe Steel | H56: 2 | I56: 5661.79 | J56: 3397.07 | K56: 0.05 | L56: 10757.4
A57: 100056 | B57: 24-Apr-2024 | C57: AADHYA SINGH | D57: WEST | E57: electronics | F57: LAPTOPS | G57: ProBook 14 | H57: 11 | I57: 46753.74 | J57: 30389.93 | K57: 0.05 | L57: 488576.56
...

Sheet Cleaned_Data
A1: Order ID | B1: Order Date | C1: Month | D1: Customer Name | E1: Region | F1: Category | G1: Sub-Category | H1: Product | I1: Quantity | J1: Unit Price | K1: Cost Price | L1: Discount | M1: Sales | N1: Profit | O1: Profit Margin %
A2: =Raw_Data!A2 -> 100001 | B2: =DATEVALUE(Raw_Data!B2) -> 45620 | C2: =TEXT(B2,"mmm-yyyy") -> Nov-2024 | D2: =PROPER(TRIM(Raw_Data!C2)) -> Vikram Rao | E2: =PROPER(TRIM(Raw_Data!D2)) -> North | F2: =PROPER(TRIM(Raw_Data!E2)) -> Electronics | G2: =PROPER(TRIM(Raw_Data!F2)) -> Monitors | H2: =Raw_Data!G2 -> ViewClear 24 | I2: =Raw_Data!H2 -> 4 | J2: =Raw_Data!I2 -> 9197.33 | K2: =Raw_Data!J2 -> 5702.34 | L2: =IF(Raw_Data!K2="",0,Raw_Data!K2) -> 0 | M2: =ROUND(I2*J2*(1-L2),2) -> 36789.32 | N2: =ROUND(M2-(I2*K2),2) -> 13979.96 | O2: =IFERROR(N2/M2,0) -> 0.3800005
A3: =Raw_Data!A3 -> 100002 | B3: =DATEVALUE(Raw_Data!B3) -> #VALUE! | C3: =TEXT(B3,"mmm-yyyy") -> #VALUE! | D3: =PROPER(TRIM(Raw_Data!C3)) -> Riya Patel | E3: =PROPER(TRIM(Raw_Data!D3)) -> West | F3: =PROPER(TRIM(Raw_Data!E3)) -> Furniture | G3: =PROPER(TRIM(Raw_Data!F3)) -> Cabinets | H3: =Raw_Data!G3 -> StorageMax Wood | I3: =Raw_Data!H3 -> 1 | J3: =Raw_Data!I3 -> 4928.63 | K3: =Raw_Data!J3 -> 3105.04 | L3: =IF(Raw_Data!K3="",0,Raw_Data!K3) -> 0 | M3: =ROUND(I3*J3*(1-L3),2) -> 4928.63 | N3: =ROUND(M3-(I3*K3),2) -> 1823.59 | O3: =IFERROR(N3/M3,0) -> 0.36999937
A4: =Raw_Data!A4 -> 100003 | B4: =DATEVALUE(Raw_Data!B4) -> #VALUE! | C4: =TEXT(B4,"mmm-yyyy") -> #VALUE! | D4: =PROPER(TRIM(Raw_Data!C4)) -> Simran Bhatt | E4: =PROPER(TRIM(Raw_Data!D4)) -> East | F4: =PROPER(TRIM(Raw_Data!E4)) -> Electronics | G4: =PROPER(TRIM(Raw_Data!F4)) -> Keyboards | H4: =Raw_Data!G4 -> GamerEdge RGB | I4: =Raw_Data!H4 -> 2 | J4: =Raw_Data!I4 -> 3337.17 | K4: =Raw_Data!J4 -> 1668.58 | L4: =IF(Raw_Data!K4="",0,Raw_Data!K4) -> 0.1 | M4: =ROUND(I4*J4*(1-L4),2) -> 6006.91 | N4: =ROUND(M4-(I4*K4),2) -> 2669.75 | O4: =IFERROR(N4/M4,0) -> 0.44444648
A5: =Raw_Data!A5 -> 100004 | B5: =DATEVALUE(Raw_Data!B5) -> 45449 | C5: =TEXT(B5,"mmm-yyyy") -> Jun-2024 | D5: =PROPER(TRIM(Raw_Data!C5)) -> Saanvi Iyer | E5: =PROPER(TRIM(Raw_Data!D5)) -> North | F5: =PROPER(TRIM(Raw_Data!E5)) -> Furniture | G5: =PROPER(TRIM(Raw_Data!F5)) -> Chairs | H5: =Raw_Data!G5 -> ClassicWood | I5: =Raw_Data!H5 -> 5 | J5: =Raw_Data!I5 -> 5246.51 | K5: =Raw_Data!J5 -> 3410.23 | L5: =IF(Raw_Data!K5="",0,Raw_Data!K5) -> 0.2 | M5: =ROUND(I5*J5*(1-L5),2) -> 20986.04 | N5: =ROUND(M5-(I5*K5),2) -> 3934.89 | O5: =IFERROR(N5/M5,0) -> 0.18750036
A6: =Raw_Data!A6 -> 100005 | B6: =DATEVALUE(Raw_Data!B6) -> 45644 | C6: =TEXT(B6,"mmm-yyyy") -> Dec-2024 | D6: =PROPER(TRIM(Raw_Data!C6)) -> Priya Kapoor | E6: =PROPER(TRIM(Raw_Data!D6)) -> South | F6: =PROPER(TRIM(Raw_Data!E6)) -> Furniture | G6: =PROPER(TRIM(Raw_Data!F6)) -> Cabinets | H6: =Raw_Data!G6 -> StorageMax Wood | I6: =Raw_Data!H6 -> 5 | J6: =Raw_Data!I6 -> 5069.6 | K6: =Raw_Data!J6 -> 3193.85 | L6: =IF(Raw_Data!K6="",0,Raw_Data!K6) -> 0.15 | M6: =ROUND(I6*J6*(1-L6),2) -> 21545.8 | N6: =ROUND(M6-(I6*K6),2) -> 5576.55 | O6: =IFERROR(N6/M6,0) -> 0.25882307
A7: =Raw_Data!A7 -> 100006 | B7: =DATEVALUE(Raw_Data!B7) -> 45420 | C7: =TEXT(B7,"mmm-yyyy") -> May-2024 | D7: =PROPER(TRIM(Raw_Data!C7)) -> Kabir Nair | E7: =PROPER(TRIM(Raw_Data!D7)) -> South | F7: =PROPER(TRIM(Raw_Data!E7)) -> Office Supplies | G7: =PROPER(TRIM(Raw_Data!F7)) -> Pens | H7: =Raw_Data!G7 -> InkFlow Gel Pack5 | I7: =Raw_Data!H7 -> 7 | J7: =Raw_Data!I7 -> 127.8 | K7: =Raw_Data!J7 -> 57.51 | L7: =IF(Raw_Data!K7="",0,Raw_Data!K7) -> 0.15 | M7: =ROUND(I7*J7*(1-L7),2) -> 760.41 | N7: =ROUND(M7-(I7*K7),2) -> 357.84 | O7: =IFERROR(N7/M7,0) -> 0.47058824
A8: =Raw_Data!A8 -> 100007 | B8: =DATEVALUE(Raw_Data!B8) -> 45610 | C8: =TEXT(B8,"mmm-yyyy") -> Nov-2024 | D8: =PROPER(TRIM(Raw_Data!C8)) -> Myra Malhotra | E8: =PROPER(TRIM(Raw_Data!D8)) -> South | F8: =PROPER(TRIM(Raw_Data!E8)) -> Clothing | G8: =PROPER(TRIM(Raw_Data!F8)) -> T-Shirts | H8: =Raw_Data!G8 -> CottonBasic | I8: =Raw_Data!H8 -> 2 | J8: =Raw_Data!I8 -> 436.44 | K8: =Raw_Data!J8 -> 196.4 | L8: =IF(Raw_Data!K8="",0,Raw_Data!K8) -> 0 | M8: =ROUND(I8*J8*(1-L8),2) -> 872.88 | N8: =ROUND(M8-(I8*K8),2) -> 480.08 | O8: =IFERROR(N8/M8,0) -> 0.54999542
A9: =Raw_Data!A9 -> 100008 | B9: =DATEVALUE(Raw_Data!B9) -> #VALUE! | C9: =TEXT(B9,"mmm-yyyy") -> #VALUE! | D9: =PROPER(TRIM(Raw_Data!C9)) -> Pooja Reddy | E9: =PROPER(TRIM(Raw_Data!D9)) -> North | F9: =PROPER(TRIM(Raw_Data!E9)) -> Office Supplies | G9: =PROPER(TRIM(Raw_Data!F9)) -> Staplers | H9: =Raw_Data!G9 -> ClickFix Standard | I9: =Raw_Data!H9 -> 5 | J9: =Raw_Data!I9 -> 221.43 | K9: =Raw_Data!J9 -> 110.72 | L9: =IF(Raw_Data!K9="",0,Raw_Data!K9) -> 0.1 | M9: =ROUND(I9*J9*(1-L9),2) -> 996.44 | N9: =ROUND(M9-(I9*K9),2) -> 442.84 | O9: =IFERROR(N9/M9,0) -> 0.44442214
A10: =Raw_Data!A10 -> 100009 | B10: =DATEVALUE(Raw_Data!B10) -> #VALUE! | C10: =TEXT(B10,"mmm-yyyy") -> #VALUE! | D10: =PROPER(TRIM(Raw_Data!C10)) -> Arjun Verma | E10: =PROPER(TRIM(Raw_Data!D10)) -> East | F10: =PROPER(TRIM(Raw_Data!E10)) -> Furniture | G10: =PROPER(TRIM(Raw_Data!F10)) -> Chairs | H10: =Raw_Data!G10 -> MeshFlex Pro | I10: =Raw_Data!H10 -> 6 | J10: =Raw_Data!I10 -> 7195.98 | K10: =Raw_Data!J10 -> 4461.51 | L10: =IF(Raw_Data!K10="",0,Raw_Data!K10) -> 0 | M10: =ROUND(I10*J10*(1-L10),2) -> 43175.88 | N10: =ROUND(M10-(I10*K10),2) -> 16406.82 | O10: =IFERROR(N10/M10,0) -> 0.37999967
A11: =Raw_Data!A11 -> 100010 | B11: =DATEVALUE(Raw_Data!B11) -> 45504 | C11: =TEXT(B11,"mmm-yyyy") -> Jul-2024 | D11: =PROPER(TRIM(Raw_Data!C11)) -> Meera Shah | E11: =PROPER(TRIM(Raw_Data!D11)) -> South | F11: =PROPER(TRIM(Raw_Data!E11)) -> Furniture | G11: =PROPER(TRIM(Raw_Data!F11)) -> Cabinets | H11: =Raw_Data!G11 -> FileSafe Steel | I11: =Raw_Data!H11 -> 5 | J11: =Raw_Data!I11 -> 5704.15 | K11: =Raw_Data!J11 -> 3422.49 | L11: =IF(Raw_Data!K11="",0,Raw_Data!K11) -> 0.1 | M11: =ROUND(I11*J11*(1-L11),2) -> 25668.68 | N11: =ROUND(M11-(I11*K11),2) -> 8556.23 | O11: =IFERROR(N11/M11,0) -> 0.33333346
A12: =Raw_Data!A12 -> 100011 | B12: =DATEVALUE(Raw_Data!B12) -> 45543 | C12: =TEXT(B12,"mmm-yyyy") -> Sep-2024 | D12: =PROPER(TRIM(Raw_Data!C12)) -> Aarav Gupta | E12: =PROPER(TRIM(Raw_Data!D12)) -> West | F12: =PROPER(TRIM(Raw_Data!E12)) -> Electronics | G12: =PROPER(TRIM(Raw_Data!F12)) -> Headphones | H12: =Raw_Data!G12 -> SoundMax Pro | I12: =Raw_Data!H12 -> 2 | J12: =Raw_Data!I12 -> 2484.88 | K12: =Raw_Data!J12 -> 1366.68 | L12: =IF(Raw_Data!K12="",0,Raw_Data!K12) -> 0.1 | M12: =ROUND(I12*J12*(1-L12),2) -> 4472.78 | N12: =ROUND(M12-(I12*K12),2) -> 1739.42 | O12: =IFERROR(N12/M12,0) -> 0.38889013
A13: =Raw_Data!A13 -> 100012 | B13: =DATEVALUE(Raw_Data!B13) -> 45581 | C13: =TEXT(B13,"mmm-yyyy") -> Oct-2024 | D13: =PROPER(TRIM(Raw_Data!C13)) -> Nikhil Das | E13: =PROPER(TRIM(Raw_Data!D13)) -> East | F13: =PROPER(TRIM(Raw_Data!E13)) -> Clothing | G13: =PROPER(TRIM(Raw_Data!F13)) -> Jackets | H13: =Raw_Data!G13 -> WinterGuard | I13: =Raw_Data!H13 -> 12 | J13: =Raw_Data!I13 -> 3000.53 | K13: =Raw_Data!J13 -> 1500.26 | L13: =IF(Raw_Data!K13="",0,Raw_Data!K13) -> 0.1 | M13: =ROUND(I13*J13*(1-L13),2) -> 32405.72 | N13: =ROUND(M13-(I13*K13),2) -> 14402.6 | O13: =IFERROR(N13/M13,0) -> 0.44444623
... A451: =Raw_Data!A451 -> 100450 | B451: =DATEVALUE(Raw_Data!B451) -> 45458 | C451: =TEXT(B451,"mmm-yyyy") -> Jun-2024 | D451: =PROPER(TRIM(Raw_Data!C451)) -> Kabir Rao | E451: =PROPER(TRIM(Raw_Data!D451)) -> South | F451: =PROPER(TRIM(Raw_Data!E451)) -> Electronics | G451: =PROPER(TRIM(Raw_Data!F451)) -> Monitors | H451: =Raw_Data!G451 -> CurveTech 32 | I451: =Raw_Data!H451 -> 10 | J451: =Raw_Data!I451 -> 20475.68 | K451: =Raw_Data!J451 -> 11875.89 | L451: =IF(Raw_Data!K451="",0,Raw_Data!K451) -> 0.2 | M451: =ROUND(I451*J451*(1-L451),2) -> 163805.44 | N451: =ROUND(M451-(I451*K451),2) -> 45046.54 | O451: =IFERROR(N451/M451,0) -> 0.27500027

Sheet Analysis
A1: RETAIL SALES — PIVOT-STYLE ANALYSIS TABLES
A3: 1. Sales & Profit by Region
A5: Region | B5: Total Sales | C5: Total Profit | D5: Profit Margin % | E5: Order Count
A6: North | B6: =SUMIF(Cleaned_Data!$E$2:$E$451,A6,Cleaned_Data!$M$2:$M$451) -> 5138084.1 | C6: =SUMIF(Cleaned_Data!$E$2:$E$451,A6,Cleaned_Data!$N$2:$N$451) -> 1719816.4 | D6: =IFERROR(C6/B6,0) -> 0.33471939 | E6: =COUNTIF(Cleaned_Data!$E$2:$E$451,A6) -> 112
A7: South | B7: =SUMIF(Cleaned_Data!$E$2:$E$451,A7,Cleaned_Data!$M$2:$M$451) -> 3879014 | C7: =SUMIF(Cleaned_Data!$E$2:$E$451,A7,Cleaned_Data!$N$2:$N$451) -> 1392611.6 | D7: =IFERROR(C7/B7,0) -> 0.35901174 | E7: =COUNTIF(Cleaned_Data!$E$2:$E$451,A7) -> 97
A8: East | B8: =SUMIF(Cleaned_Data!$E$2:$E$451,A8,Cleaned_Data!$M$2:$M$451) -> 3586208.1 | C8: =SUMIF(Cleaned_Data!$E$2:$E$451,A8,Cleaned_Data!$N$2:$N$451) -> 1274161.2 | D8: =IFERROR(C8/B8,0) -> 0.35529481 | E8: =COUNTIF(Cleaned_Data!$E$2:$E$451,A8) -> 119
A9: West | B9: =SUMIF(Cleaned_Data!$E$2:$E$451,A9,Cleaned_Data!$M$2:$M$451) -> 4866661.9 | C9: =SUMIF(Cleaned_Data!$E$2:$E$451,A9,Cleaned_Data!$N$2:$N$451) -> 1647181.3 | D9: =IFERROR(C9/B9,0) -> 0.33846224 | E9: =COUNTIF(Cleaned_Data!$E$2:$E$451,A9) -> 122
A10: TOTAL | B10: =SUM(B6:B9) -> 17469968 | C10: =SUM(C6:C9) -> 6033770.4 | D10: =IFERROR(C10/B10,0) -> 0.34537959 | E10: =SUM(E6:E9) -> 450
A12: 2. Sales & Profit by Category
A13: Category | B13: Total Sales | C13: Total Profit | D13: Profit Margin % | E13: Order Count
A14: Electronics | B14: =SUMIF(Cleaned_Data!$F$2:$F$451,A14,Cleaned_Data!$M$2:$M$451) -> 12274030 | C14: =SUMIF(Cleaned_Data!$F$2:$F$451,A14,Cleaned_Data!$N$2:$N$451) -> 4113842.2 | D14: =IFERROR(C14/B14,0) -> 0.33516637 | E14: =COUNTIF(Cleaned_Data!$F$2:$F$451,A14) -> 121
A15: Furniture | B15: =SUMIF(Cleaned_Data!$F$2:$F$451,A15,Cleaned_Data!$M$2:$M$451) -> 3768787.6 | C15: =SUMIF(Cleaned_Data!$F$2:$F$451,A15,Cleaned_Data!$N$2:$N$451) -> 1245849.8 | D15: =IFERROR(C15/B15,0) -> 0.33057045 | E15: =COUNTIF(Cleaned_Data!$F$2:$F$451,A15) -> 113
A16: Office Supplies | B16: =SUMIF(Cleaned_Data!$F$2:$F$451,A16,Cleaned_Data!$M$2:$M$451) -> 141223.65 | C16: =SUMIF(Cleaned_Data!$F$2:$F$451,A16,Cleaned_Data!$N$2:$N$451) -> 66719.82 | D16: =IFERROR(C16/B16,0) -> 0.47244084 | E16: =COUNTIF(Cleaned_Data!$F$2:$F$451,A16) -> 106
A17: Clothing | B17: =SUMIF(Cleaned_Data!$F$2:$F$451,A17,Cleaned_Data!$M$2:$M$451) -> 1285926.5 | C17: =SUMIF(Cleaned_Data!$F$2:$F$451,A17,Cleaned_Data!$N$2:$N$451) -> 607358.54 | D17: =IFERROR(C17/B17,0) -> 0.47231202 | E17: =COUNTIF(Cleaned_Data!$F$2:$F$451,A17) -> 110
A18: TOTAL | B18: =SUM(B14:B17) -> 17469968 | C18: =SUM(C14:C17) -> 6033770.4 | D18: =IFERROR(C18/B18,0) -> 0.34537959 | E18: =SUM(E14:E17) -> 450
A20: 3. Monthly Sales & Profit Trend (2024)
A21: Month | B21: Total Sales | C21: Total Profit | D21: Order Count
A22: Jan-2024 | B22: =SUMIF(Cleaned_Data!$C$2:$C$451,A22,Cleaned_Data!$M$2:$M$451) -> 837204.17 | C22: =SUMIF(Cleaned_Data!$C$2:$C$451,A22,Cleaned_Data!$N$2:$N$451) -> 290816.93 | D22: =COUNTIF(Cleaned_Data!$C$2:$C$451,A22) -> 14
A23: Feb-2024 | B23: =SUMIF(Cleaned_Data!$C$2:$C$451,A23,Cleaned_Data!$M$2:$M$451) -> 1695632.5 | C23: =SUMIF(Cleaned_Data!$C$2:$C$451,A23,Cleaned_Data!$N$2:$N$451) -> 554398.31 | D23: =COUNTIF(Cleaned_Data!$C$2:$C$451,A23) -> 28
A24: Mar-2024 | B24: =SUMIF(Cleaned_Data!$C$2:$C$451,A24,Cleaned_Data!$M$2:$M$451) -> 1140317.9 | C24: =SUMIF(Cleaned_Data!$C$2:$C$451,A24,Cleaned_Data!$N$2:$N$451) -> 408277.9 | D24: =COUNTIF(Cleaned_Data!$C$2:$C$451,A24) -> 32
A25: Apr-2024 | B25: =SUMIF(Cleaned_Data!$C$2:$C$451,A25,Cleaned_Data!$M$2:$M$451) -> 979561.9 | C25: =SUMIF(Cleaned_Data!$C$2:$C$451,A25,Cleaned_Data!$N$2:$N$451) -> 315462.35 | D25: =COUNTIF(Cleaned_Data!$C$2:$C$451,A25) -> 19
A26: May-2024 | B26: =SUMIF(Cleaned_Data!$C$2:$C$451,A26,Cleaned_Data!$M$2:$M$451) -> 822936.97 | C26: =SUMIF(Cleaned_Data!$C$2:$C$451,A26,Cleaned_Data!$N$2:$N$451) -> 308062.78 | D26: =COUNTIF(Cleaned_Data!$C$2:$C$451,A26) -> 22
A27: Jun-2024 | B27: =SUMIF(Cleaned_Data!$C$2:$C$451,A27,Cleaned_Data!$M$2:$M$451) -> 1493680.4 | C27: =SUMIF(Cleaned_Data!$C$2:$C$451,A27,Cleaned_Data!$N$2:$N$451) -> 532680.43 | D27: =COUNTIF(Cleaned_Data!$C$2:$C$451,A27) -> 32
A28: Jul-2024 | B28: =SUMIF(Cleaned_Data!$C$2:$C$451,A28,Cleaned_Data!$M$2:$M$451) -> 1550352.5 | C28: =SUMIF(Cleaned_Data!$C$2:$C$451,A28,Cleaned_Data!$N$2:$N$451) -> 536234.7 | D28: =COUNTIF(Cleaned_Data!$C$2:$C$451,A28) -> 35
A29: Aug-2024 | B29: =SUMIF(Cleaned_Data!$C$2:$C$451,A29,Cleaned_Data!$M$2:$M$451) -> 493646.9 | C29: =SUMIF(Cleaned_Data!$C$2:$C$451,A29,Cleaned_Data!$N$2:$N$451) -> 186228.28 | D29: =COUNTIF(Cleaned_Data!$C$2:$C$451,A29) -> 24
A30: Sep-2024 | B30: =SUMIF(Cleaned_Data!$C$2:$C$451,A30,Cleaned_Data!$M$2:$M$451) -> 552593.95 | C30: =SUMIF(Cleaned_Data!$C$2:$C$451,A30,Cleaned_Data!$N$2:$N$451) -> 201197.71 | D30: =COUNTIF(Cleaned_Data!$C$2:$C$451,A30) -> 27
A31: Oct-2024 | B31: =SUMIF(Cleaned_Data!$C$2:$C$451,A31,Cleaned_Data!$M$2:$M$451) -> 551075.05 | C31: =SUMIF(Cleaned_Data!$C$2:$C$451,A31,Cleaned_Data!$N$2:$N$451) -> 184074.57 | D31: =COUNTIF(Cleaned_Data!$C$2:$C$451,A31) -> 16
A32: Nov-2024 | B32: =SUMIF(Cleaned_Data!$C$2:$C$451,A32,Cleaned_Data!$M$2:$M$451) -> 1453830.7 | C32: =SUMIF(Cleaned_Data!$C$2:$C$451,A32,Cleaned_Data!$N$2:$N$451) -> 461457.4 | D32: =COUNTIF(Cleaned_Data!$C$2:$C$451,A32) -> 23
A33: Dec-2024 | B33: =SUMIF(Cleaned_Data!$C$2:$C$451,A33,Cleaned_Data!$M$2:$M$451) -> 486924.47 | C33: =SUMIF(Cleaned_Data!$C$2:$C$451,A33,Cleaned_Data!$N$2:$N$451) -> 189930.33 | D33: =COUNTIF(Cleaned_Data!$C$2:$C$451,A33) -> 31
A34: TOTAL | B34: =SUM(B22:B33) -> 12057758 | C34: =SUM(C22:C33) -> 4168821.7 | D34: =SUM(D22:D33) -> 303
A36: 4. Top 10 Best-Selling Products by Revenue
A37: Product | B37: Total Sales | C37: Total Profit | D37: Units Sold
A38: ProBook 14 | B38: =SUMIF(Cleaned_Data!$H$2:$H$451,A38,Cleaned_Data!$M$2:$M$451) -> 4117343.7 | C38: =SUMIF(Cleaned_Data!$H$2:$H$451,A38,Cleaned_Data!$N$2:$N$451) -> 1298059.9 | D38: =SUMIF(Cleaned_Data!$H$2:$H$451,A38,Cleaned_Data!$I$2:$I$451) -> 96
A39: UltraSlim X1 | B39: =SUMIF(Cleaned_Data!$H$2:$H$451,A39,Cleaned_Data!$M$2:$M$451) -> 3662980.2 | C39: =SUMIF(Cleaned_Data!$H$2:$H$451,A39,Cleaned_Data!$N$2:$N$451) -> 1253706.5 | D39: =SUMIF(Cleaned_Data!$H$2:$H$451,A39,Cleaned_Data!$I$2:$I$451) -> 64
A40: ErgoComfort | B40: =SUMIF(Cleaned_Data!$H$2:$H$451,A40,Cleaned_Data!$M$2:$M$451) -> 306573.29 | C40: =SUMIF(Cleaned_Data!$H$2:$H$451,A40,Cleaned_Data!$N$2:$N$451) -> 106712.29 | D40: =SUMIF(Cleaned_Data!$H$2:$H$451,A40,Cleaned_Data!$I$2:$I$451) -> 38
A41: CornerFit Desk | B41: =SUMIF(Cleaned_Data!$H$2:$H$451,A41,Cleaned_Data!$M$2:$M$451) -> 786773.23 | C41: =SUMIF(Cleaned_Data!$H$2:$H$451,A41,Cleaned_Data!$N$2:$N$451) -> 293142.25 | D41: =SUMIF(Cleaned_Data!$H$2:$H$451,A41,Cleaned_Data!$I$2:$I$451) -> 85
A42: WideView 27 | B42: =SUMIF(Cleaned_Data!$H$2:$H$451,A42,Cleaned_Data!$M$2:$M$451) -> 860377.98 | C42: =SUMIF(Cleaned_Data!$H$2:$H$451,A42,Cleaned_Data!$N$2:$N$451) -> 299959.94 | D42: =SUMIF(Cleaned_Data!$H$2:$H$451,A42,Cleaned_Data!$I$2:$I$451) -> 65
A43: CurveTech 32 | B43: =SUMIF(Cleaned_Data!$H$2:$H$451,A43,Cleaned_Data!$M$2:$M$451) -> 1358240.8 | C43: =SUMIF(Cleaned_Data!$H$2:$H$451,A43,Cleaned_Data!$N$2:$N$451) -> 462879.49 | D43: =SUMIF(Cleaned_Data!$H$2:$H$451,A43,Cleaned_Data!$I$2:$I$451) -> 72
A44: MeshFlex Pro | B44: =SUMIF(Cleaned_Data!$H$2:$H$451,A44,Cleaned_Data!$M$2:$M$451) -> 503060.45 | C44: =SUMIF(Cleaned_Data!$H$2:$H$451,A44,Cleaned_Data!$N$2:$N$451) -> 171728.06 | D44: =SUMIF(Cleaned_Data!$H$2:$H$451,A44,Cleaned_Data!$I$2:$I$451) -> 74
A45: WinterGuard | B45: =SUMIF(Cleaned_Data!$H$2:$H$451,A45,Cleaned_Data!$M$2:$M$451) -> 221767.25 | C45: =SUMIF(Cleaned_Data!$H$2:$H$451,A45,Cleaned_Data!$N$2:$N$451) -> 103530.09 | D45: =SUMIF(Cleaned_Data!$H$2:$H$451,A45,Cleaned_Data!$I$2:$I$451) -> 82
...

Sheet Dashboard
A1: RETAIL SALES & OPERATIONS DASHBOARD
A2: FY 2024 | Source: Cleaned_Data | All figures in ₹
A4: Total Revenue | C4: Total Profit | E4: Total Orders | G4: Avg Order Value
A5: =Analysis!B10 -> 17469968 | C5: =Analysis!C10 -> 6033770.4 | E5: =Analysis!E10 -> 450 | G5: =Analysis!B10/Analysis!E10 -> 38822.152

Sheet Summary_Recommendations
A1: EXECUTIVE SUMMARY & RECOMMENDATIONS
A3: Key Findings
A4: ="Top-performing region: " & INDEX(Analysis!A6:A9,MATCH(MAX(Analysis!B6:B9),Analysis!B6:B9,0)) & " generated the highest revenue at ₹" & TEXT(MAX(Analysis!B6:B9),"#,##0") & "." -> Top-performing region: North generated the highest revenue at ₹51,38,084.
A5: ="Weakest region: " & INDEX(Analysis!A6:A9,MATCH(MIN(Analysis!B6:B9),Analysis!B6:B9,0)) & " trails with revenue of ₹" & TEXT(MIN(Analysis!B6:B9),"#,##0") & ", a gap worth investigating." -> Weakest region: East trails with revenue of ₹35,86,208, a gap worth investigating.
A6: ="Top category by revenue: " & INDEX(Analysis!A14:A17,MATCH(MAX(Analysis!B14:B17),Analysis!B14:B17,0)) & ", contributing ₹" & TEXT(MAX(Analysis!B14:B17),"#,##0") & " in sales." -> Top category by revenue: Electronics, contributing ₹1,22,74,030 in sales.
A7: ="Highest-margin category: " & INDEX(Analysis!A14:A17,MATCH(MAX(Analysis!D14:D17),Analysis!D14:D17,0)) & " at " & TEXT(MAX(Analysis!D14:D17),"0.0%") & " profit margin — more profitable per rupee of sale than the top-revenue category." -> Highest-margin category: Office Supplies at 47.2% profit margin — more profitable per rupee of sale than the top-revenue category.
A8: ="Best sales month: " & INDEX(Analysis!A22:A33,MATCH(MAX(Analysis!B22:B33),Analysis!B22:B33,0)) & " with ₹" & TEXT(MAX(Analysis!B22:B33),"#,##0") & " in revenue." -> Best sales month: Feb-2024 with ₹16,95,632 in revenue.
A9: ="Slowest sales month: " & INDEX(Analysis!A22:A33,MATCH(MIN(Analysis!B22:B33),Analysis!B22:B33,0)) & " with only ₹" & TEXT(MIN(Analysis!B22:B33),"#,##0") & " in revenue — worth checking for seasonality or stock issues." -> Slowest sales month: Dec-2024 with only ₹4,86,924 in revenue — worth checking for seasonality or stock issues.
A10: ="Best-selling product: " & INDEX(Analysis!A38:A47,MATCH(MAX(Analysis!B38:B47),Analysis!B38:B47,0)) & ", generating ₹" & TEXT(MAX(Analysis!B38:B47),"#,##0") & " in revenue." -> Best-selling product: ProBook 14, generating ₹41,17,344 in revenue.
A11: ="Overall profit margin across all sales: " & TEXT(Analysis!D10,"0.0%") & " on total revenue of ₹" & TEXT(Analysis!B10,"#,##0") & "." -> Overall profit margin across all sales: 34.5% on total revenue of ₹1,74,69,968.
A13: Recommendations
A14: 1. Reallocate marketing spend toward the weakest-performing region — run a targeted promotion and compare next quarter's results.
A15: 2. Office Supplies and Clothing carry the highest profit margins despite lower revenue — bundle them with top-selling Electronics items to lift overall margin.
A16: 3. Investigate the slowest sales month for stock-outs, pricing issues, or seasonal demand drops before assuming it's a marketing problem.
A17: 4. Double down on the top 3 best-selling products with better in-stock availability and featured placement, since they already drive a disproportionate share of revenue.
A18: 5. Standardize data entry (region names, customer names, date formats) at the source — this dataset required significant cleaning, which signals an opportunity to fix the input process, not just the output report.
A19: 6. Set up this workbook to refresh monthly: drop new transactions into Raw_Data, and every formula in Cleaned_Data, Analysis, and Dashboard updates automatically.
A21: Methodology Note
A22: Raw_Data contains 468 transaction records as originally logged, including inconsistent text casing/spacing, two different date formats, missing Discount/Sales values, and 18 duplicate entries. Cleaned_Data rebuilds every field with formulas (TRIM, PROPER, DATEVALUE) and recalculates Sales and Profit from source fields rather than trusting the raw, error-prone Sales column. Duplicate records were identified by Order ID and excluded from the clean table. Analysis uses SUMIF/COUNTIF pivot-style summaries instead of static numbers so the whole report recalculates if new data is added.
